Workbook
Name HeuresParJour: 'Paramètres'!$B$2

Sheet Synthèse
A1: Format | B1: Reste à engager
A2: Version | B2: 1
A4: A.ABC.26001 — Contrôle d’accès du site de Lyon
A6: Entreprise | B6: Exemple Industrie
A7: Client | B7: Client Exemple
A8: Révision | B8: Revue de février (en cours)
A9: Revue du | B9: 2027-02-15
A10: Structure | B10: Structure principale
A11: Devise | B11: EUR
H14: Ventilation du reste à engager
A15: Sous-projet | B15: Budget | C15: Coûts réels | D15: Reste à engager | E15: Projection | F15: Écart au budget | G15: Avancement financier | H15: Reste — Main-d’œuvre | I15: Reste — Fournitures | J15: Reste — Sous-traitance | K15: Reste — Provisions pour risques | L15: Jours I810 | M15: Jours I329 | N15: Jours I1M2
A16: SP-PRE Prestations | B16: ='SP-PRE'!$B$4 -> 0 | C16: ='SP-PRE'!$B$5 -> 0 | D16: ='SP-PRE'!$B$9 -> 0 | E16: ='SP-PRE'!$B$10 -> 0 | F16: ='SP-PRE'!$B$11 -> 0 | G16: ='SP-PRE'!$B$12 -> 0 | H16: =SUMIFS(RAE_SP_PRE[[Reste à engager]],RAE_SP_PRE[[Nature]],"Main-d’œuvre") -> 0 | I16: =SUMIFS(RAE_SP_PRE[[Reste à engager]],RAE_SP_PRE[[Nature]],"Fournitures") -> 0 | J16: =SUMIFS(RAE_SP_PRE[[Reste à engager]],RAE_SP_PRE[[Nature]],"Sous-traitance") -> 0 | K16: ='SP-PRE'!$B$7 -> 0 | L16: =SUMIFS(RAE_SP_PRE[[Jours restants]],RAE_SP_PRE[[Code comptable]],"I810") -> 0 | M16: =SUMIFS(RAE_SP_PRE[[Jours restants]],RAE_SP_PRE[[Code comptable]],"I329") -> 0 | N16: =SUMIFS(RAE_SP_PRE[[Jours restants]],RAE_SP_PRE[[Code comptable]],"I1M2") -> 0
A17: SP-MAT Matériel | B17: ='SP-MAT'!$B$4 -> 0 | C17: ='SP-MAT'!$B$5 -> 0 | D17: ='SP-MAT'!$B$9 -> 0 | E17: ='SP-MAT'!$B$10 -> 0 | F17: ='SP-MAT'!$B$11 -> 0 | G17: ='SP-MAT'!$B$12 -> 0 | H17: =SUMIFS(RAE_SP_MAT[[Reste à engager]],RAE_SP_MAT[[Nature]],"Main-d’œuvre") -> 0 | I17: =SUMIFS(RAE_SP_MAT[[Reste à engager]],RAE_SP_MAT[[Nature]],"Fournitures") -> 0 | J17: =SUMIFS(RAE_SP_MAT[[Reste à engager]],RAE_SP_MAT[[Nature]],"Sous-traitance") -> 0 | K17: ='SP-MAT'!$B$7 -> 0 | L17: =SUMIFS(RAE_SP_MAT[[Jours restants]],RAE_SP_MAT[[Code comptable]],"I810") -> 0 | M17: =SUMIFS(RAE_SP_MAT[[Jours restants]],RAE_SP_MAT[[Code comptable]],"I329") -> 0 | N17: =SUMIFS(RAE_SP_MAT[[Jours restants]],RAE_SP_MAT[[Code comptable]],"I1M2") -> 0
A18: Hors sous-projet | B18: ='Hors sous-projet'!$B$4 -> 0 | C18: ='Hors sous-projet'!$B$5 -> 0 | D18: ='Hors sous-projet'!$B$9 -> 0 | E18: ='Hors sous-projet'!$B$10 -> 0 | F18: ='Hors sous-projet'!$B$11 -> 0 | G18: ='Hors sous-projet'!$B$12 -> 0 | H18: =SUMIFS(RAE_Hors_sous_projet[[Reste à engager]],RAE_Hors_sous_projet[[Nature]],"Main-d’œuvre") -> 0 | I18: =SUMIFS(RAE_Hors_sous_projet[[Reste à engager]],RAE_Hors_sous_projet[[Nature]],"Fournitures") -> 0 | J18: =SUMIFS(RAE_Hors_sous_projet[[Reste à engager]],RAE_Hors_sous_projet[[Nature]],"Sous-traitance") -> 0 | K18: ='Hors sous-projet'!$B$7 -> 0 | L18: =SUMIFS(RAE_Hors_sous_projet[[Jours restants]],RAE_Hors_sous_projet[[Code comptable]],"I810") -> 0 | M18: =SUMIFS(RAE_Hors_sous_projet[[Jours restants]],RAE_Hors_sous_projet[[Code comptable]],"I329") -> 0 | N18: =SUMIFS(RAE_Hors_sous_projet[[Jours restants]],RAE_Hors_sous_projet[[Code comptable]],"I1M2") -> 0
A19: Projet | B19: =SUM(B16:B18) -> 0 | C19: =SUM(C16:C18) -> 0 | D19: =SUM(D16:D18) -> 0 | E19: =SUM(E16:E18) -> 0 | F19: =SUM(F16:F18) -> 0 | G19: =IF(E19=0,"non calculable",C19/E19) -> 0 | H19: =SUM(H16:H18) -> 0 | I19: =SUM(I16:I18) -> 0 | J19: =SUM(J16:J18) -> 0 | K19: =SUM(K16:K18) -> 0 | L19: =SUM(L16:L18) -> 0 | M19: =SUM(M16:M18) -> 0 | N19: =SUM(N16:N18) -> 0
A21: Écart signé dans le sens de la dérive : positif quand le sous-projet coûte plus que son budget (WF-RAE-0020). Avancement financier : coûts réels sur projection (WF-IND-0040).
A23: © 2027 Exemple Industrie — Généré par Waterfall le 2027-02-15 — logiciel libre sous licence AGPL-3.0 — www.waterfall-project.pro

Sheet SP-PRE
A1: SP-PRE Prestations
A2: Revue du 2027-02-15 — une ligne par rôle ou par débours, comme au devis. La main-d’œuvre se saisit en jours de 8 heures, un débours en montant.
A4: Budget du sous-projet | B4: 68567.6
A5: Coûts réels imputés | B5: 21500
A6: Reste à engager du tableau | B6: =SUBTOTAL(109,RAE_SP_PRE[[Reste à engager]]) -> 0
A7: Provisions des risques identifiés | B7: 0
A9: Reste à engager | B9: =$B$6+$B$7 -> 0
A10: Projection (coûts réels + reste) | B10: =$B$5+$B$9 -> 0
A11: Écart au budget | B11: =$B$10-$B$4 -> 0
A12: Avancement financier | B12: =IF($B$10=0,"non calculable",$B$5/$B$10) -> 0
H14: Reste au 2027-02-15
A15: Tâche | B15: Description de la tâche | C15: État | D15: Rôle ou catégorie | E15: Désignation | F15: Budget | G15: Reste précédent | H15: Jours restants | I15: Débours restant | J15: Nature | K15: Code comptable | L15: Service | M15: Taux horaire | N15: Main-d’œuvre | O15: Débours | P15: Reste à engager | Q15: Type | R15: Coefficient | S15: ID ligne
A16: 1.1.1 Management | B16: =IF(RAE_SP_PRE[[#This Row],[Tâche]]="","",IFERROR(INDEX(Taches[[Description]],MATCH(RAE_SP_PRE[[#This Row],[Tâche]],Taches[[Entrée]],0)),"")) -> 0 | C16: =IF(RAE_SP_PRE[[#This Row],[Tâche]]="","",IFERROR(INDEX(Taches[[État]],MATCH(RAE_SP_PRE[[#This Row],[Tâche]],Taches[[Entrée]],0)),"")) -> 0 | D16: Responsable d’affaire A1 (RA-A1) | F16: 3700 | G16: 1480 | H16: 3 | J16: =IF(RAE_SP_PRE[[#This Row],[Rôle ou catégorie]]="","",IFERROR(INDEX(Referentiel[[Nature]],MATCH(RAE_SP_PRE[[#This Row],[Rôle ou catégorie]],Referentiel[[Entrée]],0)),"?")) -> 0 | K16: =IF(RAE_SP_PRE[[#This Row],[Rôle ou catégorie]]="","",IFERROR(INDEX(Referentiel[[Code comptable]],MATCH(RAE_SP_PRE[[#This Row],[Rôle ou catégorie]],Referentiel[[Entrée]],0)),"?")) -> 0 | L16: =IF(RAE_SP_PRE[[#This Row],[Rôle ou catégorie]]="","",IFERROR(INDEX(Referentiel[[Service]],MATCH(RAE_SP_PRE[[#This Row],[Rôle ou catégorie]],Referentiel[[Entrée]],0)),"?")&"") -> 0 | M16: =IF(RAE_SP_PRE[[#This Row],[Rôle ou catégorie]]="","",IFERROR(INDEX(Referentiel[[Taux horaire]],MATCH(RAE_SP_PRE[[#This Row],[Rôle ou catégorie]],Referentiel[[Entrée]],0)),"?")) -> 0 | N16: =IF(RAE_SP_PRE[[#This Row],[Rôle ou catégorie]]="","",IF(RAE_SP_PRE[[#This Row],[Type]]="Main-d’œuvre",N(RAE_SP_PRE[[#This Row],[Jours restants]])*HeuresParJour*RAE_SP_PRE[[#This Row],[Taux horaire]]*RAE_SP_PRE[[#This Row],[Coefficient]],0)) -> 0 | O16: =IF(RAE_SP_PRE[[#This Row],[Rôle ou catégorie]]="","",IF(RAE_SP_PRE[[#This Row],[Type]]="Hors main-d’œuvre",N(RAE_SP_PRE[[#This Row],[Débours restant]]),0)) -> 0 | P16: =IF(RAE_SP_PRE[[#This Row],[Rôle ou catégorie]]="","",RAE_SP_PRE[[#This Row],[Main-d’œuvre]]+RAE_SP_PRE[[#This Row],[Débours]]) -> 0 | Q16: =IF(RAE_SP_PRE[[#This Row],[Rôle ou catégorie]]="","",IFERROR(INDEX(Referentiel[[Type de nature]],MATCH(RAE_SP_PRE[[#This Row],[Rôle ou catégorie]],Referentiel[[Entrée]],0)),"?")) -> 0 | R16: =IFERROR(INDEX(Taches[[Coefficient]],MATCH(RAE_SP_PRE[[#This Row],[Tâche]],Taches[[Entrée]],0)),1) -> 0 | S16: l-0101
A17: 1.1.2 Développement du logiciel | B17: =IF(RAE_SP_PRE[[#This Row],[Tâche]]="","",IFERROR(INDEX(Taches[[Description]],MATCH(RAE_SP_PRE[[#This Row],[Tâche]],Taches[[Entrée]],0)),"")) -> 0 | C17: =IF(RAE_SP_PRE[[#This Row],[Tâche]]="","",IFERROR(INDEX(Taches[[État]],MATCH(RAE_SP_PRE[[#This Row],[Tâche]],Taches[[Entrée]],0)),"")) -> 0 | D17: Architecte logiciel (ARCH-LOG) | F17: 11840 | G17: 6000 | H17: 8 | J17: =IF(RAE_SP_PRE[[#This Row],[Rôle ou catégorie]]="","",IFERROR(INDEX(Referentiel[[Nature]],MATCH(RAE_SP_PRE[[#This Row],[Rôle ou catégorie]],Referentiel[[Entrée]],0)),"?")) -> 0 | K17: =IF(RAE_SP_PRE[[#This Row],[Rôle ou catégorie]]="","",IFERROR(INDEX(Referentiel[[Code comptable]],MATCH(RAE_SP_PRE[[#This Row],[Rôle ou catégorie]],Referentiel[[Entrée]],0)),"?")) -> 0 | L17: =IF(RAE_SP_PRE[[#This Row],[Rôle ou catégorie]]="","",IFERROR(INDEX(Referentiel[[Service]],MATCH(RAE_SP_PRE[[#This Row],[Rôle ou catégorie]],Referentiel[[Entrée]],0)),"?")&"") -> 0 | M17: =IF(RAE_SP_PRE[[#This Row],[Rôle ou catégorie]]="","",IFERROR(INDEX(Referentiel[[Taux horaire]],MATCH(RAE_SP_PRE[[#This Row],[Rôle ou catégorie]],Referentiel[[Entrée]],0)),"?")) -> 0 | N17: =IF(RAE_SP_PRE[[#This Row],[Rôle ou catégorie]]="","",IF(RAE_SP_PRE[[#This Row],[Type]]="Main-d’œuvre",N(RAE_SP_PRE[[#This Row],[Jours restants]])*HeuresParJour*RAE_SP_PRE[[#This Row],[Taux horaire]]*RAE_SP_PRE[[#This Row],[Coefficient]],0)) -> 0 | O17: =IF(RAE_SP_PRE[[#This Row],[Rôle ou catégorie]]="","",IF(RAE_SP_PRE[[#This Row],[Type]]="Hors main-d’œuvre",N(RAE_SP_PRE[[#This Row],[Débours restant]]),0)) -> 0 | P17: =IF(RAE_SP_PRE[[#This Row],[Rôle ou catégorie]]="","",RAE_SP_PRE[[#This Row],[Main-d’œuvre]]+RAE_SP_PRE[[#This Row],[Débours]]) -> 0 | Q17: =IF(RAE_SP_PRE[[#This Row],[Rôle ou catégorie]]="","",IFERROR(INDEX(Referentiel[[Type de nature]],MATCH(RAE_SP_PRE[[#This Row],[Rôle ou catégorie]],Referentiel[[Entrée]],0)),"?")) -> 0 | R17: =IFERROR(INDEX(Taches[[Coefficient]],MATCH(RAE_SP_PRE[[#This Row],[Tâche]],Taches[[Entrée]],0)),1) -> 0 | S17: l-0102
A18: 1.1.2 Développement du logiciel | B18: =IF(RAE_SP_PRE[[#This Row],[Tâche]]="","",IFERROR(INDEX(Taches[[Description]],MATCH(RAE_SP_PRE[[#This Row],[Tâche]],Taches[[Entrée]],0)),"")) -> 0 | C18: =IF(RAE_SP_PRE[[#This Row],[Tâche]]="","",IFERROR(INDEX(Taches[[État]],MATCH(RAE_SP_PRE[[#This Row],[Tâche]],Taches[[Entrée]],0)),"")) -> 0 | D18: Développeur (DEV) | F18: 26640 | G18: 18300 | H18: 35 | J18: =IF(RAE_SP_PRE[[#This Row],[Rôle ou catégorie]]="","",IFERROR(INDEX(Referentiel[[Nature]],MATCH(RAE_SP_PRE[[#This Row],[Rôle ou catégorie]],Referentiel[[Entrée]],0)),"?")) -> 0 | K18: =IF(RAE_SP_PRE[[#This Row],[Rôle ou catégorie]]="","",IFERROR(INDEX(Referentiel[[Code comptable]],MATCH(RAE_SP_PRE[[#This Row],[Rôle ou catégorie]],Referentiel[[Entrée]],0)),"?")) -> 0 | L18: =IF(RAE_SP_PRE[[#This Row],[Rôle ou catégorie]]="","",IFERROR(INDEX(Referentiel[[Service]],MATCH(RAE_SP_PRE[[#This Row],[Rôle ou catégorie]],Referentiel[[Entrée]],0)),"?")&"") -> 0 | M18: =IF(RAE_SP_PRE[[#This Row],[Rôle ou catégorie]]="","",IFERROR(INDEX(Referentiel[[Taux horaire]],MATCH(RAE_SP_PRE[[#This Row],[Rôle ou catégorie]],Referentiel[[Entrée]],0)),"?")) -> 0 | N18: =IF(RAE_SP_PRE[[#This Row],[Rôle ou catégorie]]="","",IF(RAE_SP_PRE[[#This Row],[Type]]="Main-d’œuvre",N(RAE_SP_PRE[[#This Row],[Jours restants]])*HeuresParJour*RAE_SP_PRE[[#This Row],[Taux horaire]]*RAE_SP_PRE[[#This Row],[Coefficient]],0)) -> 0 | O18: =IF(RAE_SP_PRE[[#This Row],[Rôle ou catégorie]]="","",IF(RAE_SP_PRE[[#This Row],[Type]]="Hors main-d’œuvre",N(RAE_SP_PRE[[#This Row],[Débours restant]]),0)) -> 0 | P18: =IF(RAE_SP_PRE[[#This Row],[Rôle ou catégorie]]="","",RAE_SP_PRE[[#This Row],[Main-d’œuvre]]+RAE_SP_PRE[[#This Row],[Débours]]) -> 0 | Q18: =IF(RAE_SP_PRE[[#This Row],[Rôle ou catégorie]]="","",IFERROR(INDEX(Referentiel[[Type de nature]],MATCH(RAE_SP_PRE[[#This Row],[Rôle ou catégorie]],Referentiel[[Entrée]],0)),"?")) -> 0 | R18: =IFERROR(INDEX(Taches[[Coefficient]],MATCH(RAE_SP_PRE[[#This Row],[Tâche]],Taches[[Entrée]],0)),1) -> 0 | S18: l-0103
A19: 1.1.2 Développement du logiciel | B19: =IF(RAE_SP_PRE[[#This Row],[Tâche]]="","",IFERROR(INDEX(Taches[[Description]],MATCH(RAE_SP_PRE[[#This Row],[Tâche]],Taches[[Entrée]],0)),"")) -> 0 | C19: =IF(RAE_SP_PRE[[#This Row],[Tâche]]="","",IFERROR(INDEX(Taches[[État]],MATCH(RAE_SP_PRE[[#This Row],[Tâche]],Taches[[Entrée]],0)),"")) -> 0 | D19: Pose sur site (st-POSE) | E19: Commande 4500000102 — recette externe | F19: 2000 | G19: 2000 | I19: 1500 | J19: =IF(RAE_SP_PRE[[#This Row],[Rôle ou catégorie]]="","",IFERROR(INDEX(Referentiel[[Nature]],MATCH(RAE_SP_PRE[[#This Row],[Rôle ou catégorie]],Referentiel[[Entrée]],0)),"?")) -> 0 | K19: =IF(RAE_SP_PRE[[#This Row],[Rôle ou catégorie]]="","",IFERROR(INDEX(Referentiel[[Code comptable]],MATCH(RAE_SP_PRE[[#This Row],[Rôle ou catégorie]],Referentiel[[Entrée]],0)),"?")) -> 0 | L19: =IF(RAE_SP_PRE[[#This Row],[Rôle ou catégorie]]="","",IFERROR(INDEX(Referentiel[[Service]],MATCH(RAE_SP_PRE[[#This Row],[Rôle ou catégorie]],Referentiel[[Entrée]],0)),"?")&"") -> 0 | M19: =IF(RAE_SP_PRE[[#This Row],[Rôle ou catégorie]]="","",IFERROR(INDEX(Referentiel[[Taux horaire]],MATCH(RAE_SP_PRE[[#This Row],[Rôle ou catégorie]],Referentiel[[Entrée]],0)),"?")) -> 0 | N19: =IF(RAE_SP_PRE[[#This Row],[Rôle ou catégorie]]="","",IF(RAE_SP_PRE[[#This Row],[Type]]="Main-d’œuvre",N(RAE_SP_PRE[[#This Row],[Jours restants]])*HeuresParJour*RAE_SP_PRE[[#This Row],[Taux horaire]]*RAE_SP_PRE[[#This Row],[Coefficient]],0)) -> 0 | O19: =IF(RAE_SP_PRE[[#This Row],[Rôle ou catégorie]]="","",IF(RAE_SP_PRE[[#This Row],[Type]]="Hors main-d’œuvre",N(RAE_SP_PRE[[#This Row],[Débours restant]]),0)) -> 0 | P19: =IF(RAE_SP_PRE[[#This Row],[Rôle ou catégorie]]="","",RAE_SP_PRE[[#This Row],[Main-d’œuvre]]+RAE_SP_PRE[[#This Row],[Débours]]) -> 0 | Q19: =IF(RAE_SP_PRE[[#This Row],[Rôle ou catégorie]]="","",IFERROR(INDEX(Referentiel[[Type de nature]],MATCH(RAE_SP_PRE[[#This Row],[Rôle ou catégorie]],Referentiel[[Entrée]],0)),"?")) -> 0 | R19: =IFERROR(INDEX(Taches[[Coefficient]],MATCH(RAE_SP_PRE[[#This Row],[Tâche]],Taches[[Entrée]],0)),1) -> 0 | S19: l-0106
A20: 1.2.2 Câblage | B20: =IF(RAE_SP_PRE[[#This Row],[Tâche]]="","",IFERROR(INDEX(Taches[[Description]],MATCH(RAE_SP_PRE[[#This Row],[Tâche]],Taches[[Entrée]],0)),"")) -> 0 | C20: =IF(RAE_SP_PRE[[#This Row],[Tâche]]="","",IFERROR(INDEX(Taches[[État]],MATCH(RAE_SP_PRE[[#This Row],[Tâche]],Taches[[Entrée]],0)),"")) -> 0 | D20: Pose sur site (st-POSE) | F20: 8670 | G20: 8670 | I20: 8670 | J20: =IF(RAE_SP_PRE[[#This Row],[Rôle ou catégorie]]="","",IFERROR(INDEX(Referentiel[[Nature]],MATCH(RAE_SP_PRE[[#This Row],[Rôle ou catégorie]],Referentiel[[Entrée]],0)),"?")) -> 0 | K20: =IF(RAE_SP_PRE[[#This Row],[Rôle ou catégorie]]="","",IFERROR(INDEX(Referentiel[[Code comptable]],MATCH(RAE_SP_PRE[[#This Row],[Rôle ou catégorie]],Referentiel[[Entrée]],0)),"?")) -> 0 | L20: =IF(RAE_SP_PRE[[#This Row],[Rôle ou catégorie]]="","",IFERROR(INDEX(Referentiel[[Service]],MATCH(RAE_SP_PRE[[#This Row],[Rôle ou catégorie]],Referentiel[[Entrée]],0)),"?")&"") -> 0 | M20: =IF(RAE_SP_PRE[[#This Row],[Rôle ou catégorie]]="","",IFERROR(INDEX(Referentiel[[Taux horaire]],MATCH(RAE_SP_PRE[[#This Row],[Rôle ou catégorie]],Referentiel[[Entrée]],0)),"?")) -> 0 | N20: =IF(RAE_SP_PRE[[#This Row],[Rôle ou catégorie]]="","",IF(RAE_SP_PRE[[#This Row],[Type]]="Main-d’œuvre",N(RAE_SP_PRE[[#This Row],[Jours restants]])*HeuresParJour*RAE_SP_PRE[[#This Row],[Taux horaire]]*RAE_SP_PRE[[#This Row],[Coefficient]],0)) -> 0 | O20: =IF(RAE_SP_PRE[[#This Row],[Rôle ou catégorie]]="","",IF(RAE_SP_PRE[[#This Row],[Type]]="Hors main-d’œuvre",N(RAE_SP_PRE[[#This Row],[Débours restant]]),0)) -> 0 | P20: =IF(RAE_SP_PRE[[#This Row],[Rôle ou catégorie]]="","",RAE_SP_PRE[[#This Row],[Main-d’œuvre]]+RAE_SP_PRE[[#This Row],[Débours]]) -> 0 | Q20: =IF(RAE_SP_PRE[[#This Row],[Rôle ou catégorie]]="","",IFERROR(INDEX(Referentiel[[Type de nature]],MATCH(RAE_SP_PRE[[#This Row],[Rôle ou catégorie]],Referentiel[[Entrée]],0)),"?")) -> 0 | R20: =IFERROR(INDEX(Taches[[Coefficient]],MATCH(RAE_SP_PRE[[#This Row],[Tâche]],Taches[[Entrée]],0)),1) -> 0 | S20: l-0203
A21: 2.1.1 Essais | B21: =IF(RAE_SP_PRE[[#This Row],[Tâche]]="","",IFERROR(INDEX(Taches[[Description]],MATCH(RAE_SP_PRE[[#This Row],[Tâche]],Taches[[Entrée]],0)),"")) -> 0 | C21: =IF(RAE_SP_PRE[[#This Row],[Tâche]]="","",IFERROR(INDEX(Taches[[État]],MATCH(RAE_SP_PRE[[#This Row],[Tâche]],Taches[[Entrée]],0)),"")) -> 0 | D21: Ingénieur qualité A1 (IQ-A1) | F21: 4528.8 | G21: 4528.8 | H21: 9.25 | J21: =IF(RAE_SP_PRE[[#This Row],[Rôle ou catégorie]]="","",IFERROR(INDEX(Referentiel[[Nature]],MATCH(RAE_SP_PRE[[#This Row],[Rôle ou catégorie]],Referentiel[[Entrée]],0)),"?")) -> 0 | K21: =IF(RAE_SP_PRE[[#This Row],[Rôle ou catégorie]]="","",IFERROR(INDEX(Referentiel[[Code comptable]],MATCH(RAE_SP_PRE[[#This Row],[Rôle ou catégorie]],Referentiel[[Entrée]],0)),"?")) -> 0 | L21: =IF(RAE_SP_PRE[[#This Row],[Rôle ou catégorie]]="","",IFERROR(INDEX(Referentiel[[Service]],MATCH(RAE_SP_PRE[[#This Row],[Rôle ou catégorie]],Referentiel[[Entrée]],0)),"?")&"") -> 0 | M21: =IF(RAE_SP_PRE[[#This Row],[Rôle ou catégorie]]="","",IFERROR(INDEX(Referentiel[[Taux horaire]],MATCH(RAE_SP_PRE[[#This Row],[Rôle ou catégorie]],Referentiel[[Entrée]],0)),"?")) -> 0 | N21: =IF(RAE_SP_PRE[[#This Row],[Rôle ou catégorie]]="","",IF(RAE_SP_PRE[[#This Row],[Type]]="Main-d’œuvre",N(RAE_SP_PRE[[#This Row],[Jours restants]])*HeuresParJour*RAE_SP_PRE[[#This Row],[Taux horaire]]*RAE_SP_PRE[[#This Row],[Coefficient]],0)) -> 0 | O21: =IF(RAE_SP_PRE[[#This Row],[Rôle ou catégorie]]="","",IF(RAE_SP_PRE[[#This Row],[Type]]="Hors main-d’œuvre",N(RAE_SP_PRE[[#This Row],[Débours restant]]),0)) -> 0 | P21: =IF(RAE_SP_PRE[[#This Row],[Rôle ou catégorie]]="","",RAE_SP_PRE[[#This Row],[Main-d’œuvre]]+RAE_SP_PRE[[#This Row],[Débours]]) -> 0 | Q21: =IF(RAE_SP_PRE[[#This Row],[Rôle ou catégorie]]="","",IFERROR(INDEX(Referentiel[[Type de nature]],MATCH(RAE_SP_PRE[[#This Row],[Rôle ou catégorie]],Referentiel[[Entrée]],0)),"?")) -> 0 | R21: =IFERROR(INDEX(Taches[[Coefficient]],MATCH(RAE_SP_PRE[[#This Row],[Tâche]],Taches[[Entrée]],0)),1) -> 0 | S21: l-0401
A22: 2.1.1 Essais | B22: =IF(RAE_SP_PRE[[#This Row],[Tâche]]="","",IFERROR(INDEX(Taches[[Description]],MATCH(RAE_SP_PRE[[#This Row],[Tâche]],Taches[[Entrée]],0)),"")) -> 0 | C22: =IF(RAE_SP_PRE[[#This Row],[Tâche]]="","",IFERROR(INDEX(Taches[[État]],MATCH(RAE_SP_PRE[[#This Row],[Tâche]],Taches[[Entrée]],0)),"")) -> 0 | D22: Ingénieur carte (ING-CARTE) | F22: 4528.8 | G22: 4528.8 | H22: 9.25 | J22: =IF(RAE_SP_PRE[[#This Row],[Rôle ou catégorie]]="","",IFERROR(INDEX(Referentiel[[Nature]],MATCH(RAE_SP_PRE[[#This Row],[Rôle ou catégorie]],Referentiel[[Entrée]],0)),"?")) -> 0 | K22: =IF(RAE_SP_PRE[[#This Row],[Rôle ou catégorie]]="","",IFERROR(INDEX(Referentiel[[Code comptable]],MATCH(RAE_SP_PRE[[#This Row],[Rôle ou catégorie]],Referentiel[[Entrée]],0)),"?")) -> 0 | L22: =IF(RAE_SP_PRE[[#This Row],[Rôle ou catégorie]]="","",IFERROR(INDEX(Referentiel[[Service]],MATCH(RAE_SP_PRE[[#This Row],[Rôle ou catégorie]],Referentiel[[Entrée]],0)),"?")&"") -> 0 | M22: =IF(RAE_SP_PRE[[#This Row],[Rôle ou catégorie]]="","",IFERROR(INDEX(Referentiel[[Taux horaire]],MATCH(RAE_SP_PRE[[#This Row],[Rôle ou catégorie]],Referentiel[[Entrée]],0)),"?")) -> 0 | N22: =IF(RAE_SP_PRE[[#This Row],[Rôle ou catégorie]]="","",IF(RAE_SP_PRE[[#This Row],[Type]]="Main-d’œuvre",N(RAE_SP_PRE[[#This Row],[Jours restants]])*HeuresParJour*RAE_SP_PRE[[#This Row],[Taux horaire]]*RAE_SP_PRE[[#This Row],[Coefficient]],0)) -> 0 | O22: =IF(RAE_SP_PRE[[#This Row],[Rôle ou catégorie]]="","",IF(RAE_SP_PRE[[#This Row],[Type]]="Hors main-d’œuvre",N(RAE_SP_PRE[[#This Row],[Débours restant]]),0)) -> 0 | P22: =IF(RAE_SP_PRE[[#This Row],[Rôle ou catégorie]]="","",RAE_SP_PRE[[#This Row],[Main-d’œuvre]]+RAE_SP_PRE[[#This Row],[Débours]]) -> 0 | Q22: =IF(RAE_SP_PRE[[#This Row],[Rôle ou catégorie]]="","",IFERROR(INDEX(Referentiel[[Type de nature]],MATCH(RAE_SP_PRE[[#This Row],[Rôle ou catégorie]],Referentiel[[Entrée]],0)),"?")) -> 0 | R22: =IFERROR(INDEX(Taches[[Coefficient]],MATCH(RAE_SP_PRE[[#This Row],[Tâche]],Taches[[Entrée]],0)),1) -> 0 | S22: l-0402
B23: =IF(RAE_SP_PRE[[#This Row],[Tâche]]="","",IFERROR(INDEX(Taches[[Description]],MATCH(RAE_SP_PRE[[#This Row],[Tâche]],Taches[[Entrée]],0)),"")) -> 0 | C23: =IF(RAE_SP_PRE[[#This Row],[Tâche]]="","",IFERROR(INDEX(Taches[[État]],MATCH(RAE_SP_PRE[[#This Row],[Tâche]],Taches[[Entrée]],0)),"")) -> 0 | J23: =IF(RAE_SP_PRE[[#This Row],[Rôle ou catégorie]]="","",IFERROR(INDEX(Referentiel[[Nature]],MATCH(RAE_SP_PRE[[#This Row],[Rôle ou catégorie]],Referentiel[[Entrée]],0)),"?")) -> 0 | K23: =IF(RAE_SP_PRE[[#This Row],[Rôle ou catégorie]]="","",IFERROR(INDEX(Referentiel[[Code comptable]],MATCH(RAE_SP_PRE[[#This Row],[Rôle ou catégorie]],Referentiel[[Entrée]],0)),"?")) -> 0 | L23: =IF(RAE_SP_PRE[[#This Row],[Rôle ou catégorie]]="","",IFERROR(INDEX(Referentiel[[Service]],MATCH(RAE_SP_PRE[[#This Row],[Rôle ou catégorie]],Referentiel[[Entrée]],0)),"?")&"") -> 0 | M23: =IF(RAE_SP_PRE[[#This Row],[Rôle ou catégorie]]="","",IFERROR(INDEX(Referentiel[[Taux horaire]],MATCH(RAE_SP_PRE[[#This Row],[Rôle ou catégorie]],Referentiel[[Entrée]],0)),"?")) -> 0 | N23: =IF(RAE_SP_PRE[[#This Row],[Rôle ou catégorie]]="","",IF(RAE_SP_PRE[[#This Row],[Type]]="Main-d’œuvre",N(RAE_SP_PRE[[#This Row],[Jours restants]])*HeuresParJour*RAE_SP_PRE[[#This Row],[Taux horaire]]*RAE_SP_PRE[[#This Row],[Coefficient]],0)) -> 0 | O23: =IF(RAE_SP_PRE[[#This Row],[Rôle ou catégorie]]="","",IF(RAE_SP_PRE[[#This Row],[Type]]="Hors main-d’œuvre",N(RAE_SP_PRE[[#This Row],[Débours restant]]),0)) -> 0 | P23: =IF(RAE_SP_PRE[[#This Row],[Rôle ou catégorie]]="","",RAE_SP_PRE[[#This Row],[Main-d’œuvre]]+RAE_SP_PRE[[#This Row],[Débours]]) -> 0 | Q23: =IF(RAE_SP_PRE[[#This Row],[Rôle ou catégorie]]="","",IFERROR(INDEX(Referentiel[[Type de nature]],MATCH(RAE_SP_PRE[[#This Row],[Rôle ou catégorie]],Referentiel[[Entrée]],0)),"?")) -> 0 | R23: =IFERROR(INDEX(Taches[[Coefficient]],MATCH(RAE_SP_PRE[[#This Row],[Tâche]],Taches[[Entrée]],0)),1) -> 0
B24: =IF(RAE_SP_PRE[[#This Row],[Tâche]]="","",IFERROR(INDEX(Taches[[Description]],MATCH(RAE_SP_PRE[[#This Row],[Tâche]],Taches[[Entrée]],0)),"")) -> 0 | C24: =IF(RAE_SP_PRE[[#This Row],[Tâche]]="","",IFERROR(INDEX(Taches[[État]],MATCH(RAE_SP_PRE[[#This Row],[Tâche]],Taches[[Entrée]],0)),"")) -> 0 | J24: =IF(RAE_SP_PRE[[#This Row],[Rôle ou catégorie]]="","",IFERROR(INDEX(Referentiel[[Nature]],MATCH(RAE_SP_PRE[[#This Row],[Rôle ou catégorie]],Referentiel[[Entrée]],0)),"?")) -> 0 | K24: =IF(RAE_SP_PRE[[#This Row],[Rôle ou catégorie]]="","",IFERROR(INDEX(Referentiel[[Code comptable]],MATCH(RAE_SP_PRE[[#This Row],[Rôle ou catégorie]],Referentiel[[Entrée]],0)),"?")) -> 0 | L24: =IF(RAE_SP_PRE[[#This Row],[Rôle ou catégorie]]="","",IFERROR(INDEX(Referentiel[[Service]],MATCH(RAE_SP_PRE[[#This Row],[Rôle ou catégorie]],Referentiel[[Entrée]],0)),"?")&"") -> 0 | M24: =IF(RAE_SP_PRE[[#This Row],[Rôle ou catégorie]]="","",IFERROR(INDEX(Referentiel[[Taux horaire]],MATCH(RAE_SP_PRE[[#This Row],[Rôle ou catégorie]],Referentiel[[Entrée]],0)),"?")) -> 0 | N24: =IF(RAE_SP_PRE[[#This Row],[Rôle ou catégorie]]="","",IF(RAE_SP_PRE[[#This Row],[Type]]="Main-d’œuvre",N(RAE_SP_PRE[[#This Row],[Jours restants]])*HeuresParJour*RAE_SP_PRE[[#This Row],[Taux horaire]]*RAE_SP_PRE[[#This Row],[Coefficient]],0)) -> 0 | O24: =IF(RAE_SP_PRE[[#This Row],[Rôle ou catégorie]]="","",IF(RAE_SP_PRE[[#This Row],[Type]]="Hors main-d’œuvre",N(RAE_SP_PRE[[#This Row],[Débours restant]]),0)) -> 0 | P24: =IF(RAE_SP_PRE[[#This Row],[Rôle ou catégorie]]="","",RAE_SP_PRE[[#This Row],[Main-d’œuvre]]+RAE_SP_PRE[[#This Row],[Débours]]) -> 0 | Q24: =IF(RAE_SP_PRE[[#This Row],[Rôle ou catégorie]]="","",IFERROR(INDEX(Referentiel[[Type de nature]],MATCH(RAE_SP_PRE[[#This Row],[Rôle ou catégorie]],Referentiel[[Entrée]],0)),"?")) -> 0 | R24: =IFERROR(INDEX(Taches[[Coefficient]],MATCH(RAE_SP_PRE[[#This Row],[Tâche]],Taches[[Entrée]],0)),1) -> 0
B25: =IF(RAE_SP_PRE[[#This Row],[Tâche]]="","",IFERROR(INDEX(Taches[[Description]],MATCH(RAE_SP_PRE[[#This Row],[Tâche]],Taches[[Entrée]],0)),"")) -> 0 | C25: =IF(RAE_SP_PRE[[#This Row],[Tâche]]="","",IFERROR(INDEX(Taches[[État]],MATCH(RAE_SP_PRE[[#This Row],[Tâche]],Taches[[Entrée]],0)),"")) -> 0 | J25: =IF(RAE_SP_PRE[[#This Row],[Rôle ou catégorie]]="","",IFERROR(INDEX(Referentiel[[Nature]],MATCH(RAE_SP_PRE[[#This Row],[Rôle ou catégorie]],Referentiel[[Entrée]],0)),"?")) -> 0 | K25: =IF(RAE_SP_PRE[[#This Row],[Rôle ou catégorie]]="","",IFERROR(INDEX(Referentiel[[Code comptable]],MATCH(RAE_SP_PRE[[#This Row],[Rôle ou catégorie]],Referentiel[[Entrée]],0)),"?")) -> 0 | L25: =IF(RAE_SP_PRE[[#This Row],[Rôle ou catégorie]]="","",IFERROR(INDEX(Referentiel[[Service]],MATCH(RAE_SP_PRE[[#This Row],[Rôle ou catégorie]],Referentiel[[Entrée]],0)),"?")&"") -> 0 | M25: =IF(RAE_SP_PRE[[#This Row],[Rôle ou catégorie]]="","",IFERROR(INDEX(Referentiel[[Taux horaire]],MATCH(RAE_SP_PRE[[#This Row],[Rôle ou catégorie]],Referentiel[[Entrée]],0)),"?")) -> 0 | N25: =IF(RAE_SP_PRE[[#This Row],[Rôle ou catégorie]]="","",IF(RAE_SP_PRE[[#This Row],[Type]]="Main-d’œuvre",N(RAE_SP_PRE[[#This Row],[Jours restants]])*HeuresParJour*RAE_SP_PRE[[#This Row],[Taux horaire]]*RAE_SP_PRE[[#This Row],[Coefficient]],0)) -> 0 | O25: =IF(RAE_SP_PRE[[#This Row],[Rôle ou catégorie]]="","",IF(RAE_SP_PRE[[#This Row],[Type]]="Hors main-d’œuvre",N(RAE_SP_PRE[[#This Row],[Débours restant]]),0)) -> 0 | P25: =IF(RAE_SP_PRE[[#This Row],[Rôle ou catégorie]]="","",RAE_SP_PRE[[#This Row],[Main-d’œuvre]]+RAE_SP_PRE[[#This Row],[Débours]]) -> 0 | Q25: =IF(RAE_SP_PRE[[#This Row],[Rôle ou catégorie]]="","",IFERROR(INDEX(Referentiel[[Type de nature]],MATCH(RAE_SP_PRE[[#This Row],[Rôle ou catégorie]],Referentiel[[Entrée]],0)),"?")) -> 0 | R25: =IFERROR(INDEX(Taches[[Coefficient]],MATCH(RAE_SP_PRE[[#This Row],[Tâche]],Taches[[Entrée]],0)),1) -> 0
B26: =IF(RAE_SP_PRE[[#This Row],[Tâche]]="","",IFERROR(INDEX(Taches[[Description]],MATCH(RAE_SP_PRE[[#This Row],[Tâche]],Taches[[Entrée]],0)),"")) -> 0 | C26: =IF(RAE_SP_PRE[[#This Row],[Tâche]]="","",IFERROR(INDEX(Taches[[État]],MATCH(RAE_SP_PRE[[#This Row],[Tâche]],Taches[[Entrée]],0)),"")) -> 0 | J26: =IF(RAE_SP_PRE[[#This Row],[Rôle ou catégorie]]="","",IFERROR(INDEX(Referentiel[[Nature]],MATCH(RAE_SP_PRE[[#This Row],[Rôle ou catégorie]],Referentiel[[Entrée]],0)),"?")) -> 0 | K26: =IF(RAE_SP_PRE[[#This Row],[Rôle ou catégorie]]="","",IFERROR(INDEX(Referentiel[[Code comptable]],MATCH(RAE_SP_PRE[[#This Row],[Rôle ou catégorie]],Referentiel[[Entrée]],0)),"?")) -> 0 | L26: =IF(RAE_SP_PRE[[#This Row],[Rôle ou catégorie]]="","",IFERROR(INDEX(Referentiel[[Service]],MATCH(RAE_SP_PRE[[#This Row],[Rôle ou catégorie]],Referentiel[[Entrée]],0)),"?")&"") -> 0 | M26: =IF(RAE_SP_PRE[[#This Row],[Rôle ou catégorie]]="","",IFERROR(INDEX(Referentiel[[Taux horaire]],MATCH(RAE_SP_PRE[[#This Row],[Rôle ou catégorie]],Referentiel[[Entrée]],0)),"?")) -> 0 | N26: =IF(RAE_SP_PRE[[#This Row],[Rôle ou catégorie]]="","",IF(RAE_SP_PRE[[#This Row],[Type]]="Main-d’œuvre",N(RAE_SP_PRE[[#This Row],[Jours restants]])*HeuresParJour*RAE_SP_PRE[[#This Row],[Taux horaire]]*RAE_SP_PRE[[#This Row],[Coefficient]],0)) -> 0 | O26: =IF(RAE_SP_PRE[[#This Row],[Rôle ou catégorie]]="","",IF(RAE_SP_PRE[[#This Row],[Type]]="Hors main-d’œuvre",N(RAE_SP_PRE[[#This Row],[Débours restant]]),0)) -> 0 | P26: =IF(RAE_SP_PRE[[#This Row],[Rôle ou catégorie]]="","",RAE_SP_PRE[[#This Row],[Main-d’œuvre]]+RAE_SP_PRE[[#This Row],[Débours]]) -> 0 | Q26: =IF(RAE_SP_PRE[[#This Row],[Rôle ou catégorie]]="","",IFERROR(INDEX(Referentiel[[Type de nature]],MATCH(RAE_SP_PRE[[#This Row],[Rôle ou catégorie]],Referentiel[[Entrée]],0)),"?")) -> 0 | R26: =IFERROR(INDEX(Taches[[Coefficient]],MATCH(RAE_SP_PRE[[#This Row],[Tâche]],Taches[[Entrée]],0)),1) -> 0
B27: =IF(RAE_SP_PRE[[#This Row],[Tâche]]="","",IFERROR(INDEX(Taches[[Description]],MATCH(RAE_SP_PRE[[#This Row],[Tâche]],Taches[[Entrée]],0)),"")) -> 0 | C27: =IF(RAE_SP_PRE[[#This Row],[Tâche]]="","",IFERROR(INDEX(Taches[[État]],MATCH(RAE_SP_PRE[[#This Row],[Tâche]],Taches[[Entrée]],0)),"")) -> 0 | J27: =IF(RAE_SP_PRE[[#This Row],[Rôle ou catégorie]]="","",IFERROR(INDEX(Referentiel[[Nature]],MATCH(RAE_SP_PRE[[#This Row],[Rôle ou catégorie]],Referentiel[[Entrée]],0)),"?")) -> 0 | K27: =IF(RAE_SP_PRE[[#This Row],[Rôle ou catégorie]]="","",IFERROR(INDEX(Referentiel[[Code comptable]],MATCH(RAE_SP_PRE[[#This Row],[Rôle ou catégorie]],Referentiel[[Entrée]],0)),"?")) -> 0 | L27: =IF(RAE_SP_PRE[[#This Row],[Rôle ou catégorie]]="","",IFERROR(INDEX(Referentiel[[Service]],MATCH(RAE_SP_PRE[[#This Row],[Rôle ou catégorie]],Referentiel[[Entrée]],0)),"?")&"") -> 0 | M27: =IF(RAE_SP_PRE[[#This Row],[Rôle ou catégorie]]="","",IFERROR(INDEX(Referentiel[[Taux horaire]],MATCH(RAE_SP_PRE[[#This Row],[Rôle ou catégorie]],Referentiel[[Entrée]],0)),"?")) -> 0 | N27: =IF(RAE_SP_PRE[[#This Row],[Rôle ou catégorie]]="","",IF(RAE_SP_PRE[[#This Row],[Type]]="Main-d’œuvre",N(RAE_SP_PRE[[#This Row],[Jours restants]])*HeuresParJour*RAE_SP_PRE[[#This Row],[Taux horaire]]*RAE_SP_PRE[[#This Row],[Coefficient]],0)) -> 0 | O27: =IF(RAE_SP_PRE[[#This Row],[Rôle ou catégorie]]="","",IF(RAE_SP_PRE[[#This Row],[Type]]="Hors main-d’œuvre",N(RAE_SP_PRE[[#This Row],[Débours restant]]),0)) -> 0 | P27: =IF(RAE_SP_PRE[[#This Row],[Rôle ou catégorie]]="","",RAE_SP_PRE[[#This Row],[Main-d’œuvre]]+RAE_SP_PRE[[#This Row],[Débours]]) -> 0 | Q27: =IF(RAE_SP_PRE[[#This Row],[Rôle ou catégorie]]="","",IFERROR(INDEX(Referentiel[[Type de nature]],MATCH(RAE_SP_PRE[[#This Row],[Rôle ou catégorie]],Referentiel[[Entrée]],0)),"?")) -> 0 | R27: =IFERROR(INDEX(Taches[[Coefficient]],MATCH(RAE_SP_PRE[[#This Row],[Tâche]],Taches[[Entrée]],0)),1) -> 0
B28: =IF(RAE_SP_PRE[[#This Row],[Tâche]]="","",IFERROR(INDEX(Taches[[Description]],MATCH(RAE_SP_PRE[[#This Row],[Tâche]],Taches[[Entrée]],0)),"")) -> 0 | C28: =IF(RAE_SP_PRE[[#This Row],[Tâche]]="","",IFERROR(INDEX(Taches[[État]],MATCH(RAE_SP_PRE[[#This Row],[Tâche]],Taches[[Entrée]],0)),"")) -> 0 | J28: =IF(RAE_SP_PRE[[#This Row],[Rôle ou catégorie]]="","",IFERROR(INDEX(Referentiel[[Nature]],MATCH(RAE_SP_PRE[[#This Row],[Rôle ou catégorie]],Referentiel[[Entrée]],0)),"?")) -> 0 | K28: =IF(RAE_SP_PRE[[#This Row],[Rôle ou catégorie]]="","",IFERROR(INDEX(Referentiel[[Code comptable]],MATCH(RAE_SP_PRE[[#This Row],[Rôle ou catégorie]],Referentiel[[Entrée]],0)),"?")) -> 0 | L28: =IF(RAE_SP_PRE[[#This Row],[Rôle ou catégorie]]="","",IFERROR(INDEX(Referentiel[[Service]],MATCH(RAE_SP_PRE[[#This Row],[Rôle ou catégorie]],Referentiel[[Entrée]],0)),"?")&"") -> 0 | M28: =IF(RAE_SP_PRE[[#This Row],[Rôle ou catégorie]]="","",IFERROR(INDEX(Referentiel[[Taux horaire]],MATCH(RAE_SP_PRE[[#This Row],[Rôle ou catégorie]],Referentiel[[Entrée]],0)),"?")) -> 0 | N28: =IF(RAE_SP_PRE[[#This Row],[Rôle ou catégorie]]="","",IF(RAE_SP_PRE[[#This Row],[Type]]="Main-d’œuvre",N(RAE_SP_PRE[[#This Row],[Jours restants]])*HeuresParJour*RAE_SP_PRE[[#This Row],[Taux horaire]]*RAE_SP_PRE[[#This Row],[Coefficient]],0)) -> 0 | O28: =IF(RAE_SP_PRE[[#This Row],[Rôle ou catégorie]]="","",IF(RAE_SP_PRE[[#This Row],[Type]]="Hors main-d’œuvre",N(RAE_SP_PRE[[#This Row],[Débours restant]]),0)) -> 0 | P28: =IF(RAE_SP_PRE[[#This Row],[Rôle ou catégorie]]="","",RAE_SP_PRE[[#This Row],[Main-d’œuvre]]+RAE_SP_PRE[[#This Row],[Débours]]) -> 0 | Q28: =IF(RAE_SP_PRE[[#This Row],[Rôle ou catégorie]]="","",IFERROR(INDEX(Referentiel[[Type de nature]],MATCH(RAE_SP_PRE[[#This Row],[Rôle ou catégorie]],Referentiel[[Entrée]],0)),"?")) -> 0 | R28: =IFERROR(INDEX(Taches[[Coefficient]],MATCH(RAE_SP_PRE[[#This Row],[Tâche]],Taches[[Entrée]],0)),1) -> 0
B29: =IF(RAE_SP_PRE[[#This Row],[Tâche]]="","",IFERROR(INDEX(Taches[[Description]],MATCH(RAE_SP_PRE[[#This Row],[Tâche]],Taches[[Entrée]],0)),"")) -> 0 | C29: =IF(RAE_SP_PRE[[#This Row],[Tâche]]="","",IFERROR(INDEX(Taches[[État]],MATCH(RAE_SP_PRE[[#This Row],[Tâche]],Taches[[Entrée]],0)),"")) -> 0 | J29: =IF(RAE_SP_PRE[[#This Row],[Rôle ou catégorie]]="","",IFERROR(INDEX(Referentiel[[Nature]],MATCH(RAE_SP_PRE[[#This Row],[Rôle ou catégorie]],Referentiel[[Entrée]],0)),"?")) -> 0 | K29: =IF(RAE_SP_PRE[[#This Row],[Rôle ou catégorie]]="","",IFERROR(INDEX(Referentiel[[Code comptable]],MATCH(RAE_SP_PRE[[#This Row],[Rôle ou catégorie]],Referentiel[[Entrée]],0)),"?")) -> 0 | L29: =IF(RAE_SP_PRE[[#This Row],[Rôle ou catégorie]]="","",IFERROR(INDEX(Referentiel[[Service]],MATCH(RAE_SP_PRE[[#This Row],[Rôle ou catégorie]],Referentiel[[Entrée]],0)),"?")&"") -> 0 | M29: =IF(RAE_SP_PRE[[#This Row],[Rôle ou catégorie]]="","",IFERROR(INDEX(Referentiel[[Taux horaire]],MATCH(RAE_SP_PRE[[#This Row],[Rôle ou catégorie]],Referentiel[[Entrée]],0)),"?")) -> 0 | N29: =IF(RAE_SP_PRE[[#This Row],[Rôle ou catégorie]]="","",IF(RAE_SP_PRE[[#This Row],[Type]]="Main-d’œuvre",N(RAE_SP_PRE[[#This Row],[Jours restants]])*HeuresParJour*RAE_SP_PRE[[#This Row],[Taux horaire]]*RAE_SP_PRE[[#This Row],[Coefficient]],0)) -> 0 | O29: =IF(RAE_SP_PRE[[#This Row],[Rôle ou catégorie]]="","",IF(RAE_SP_PRE[[#This Row],[Type]]="Hors main-d’œuvre",N(RAE_SP_PRE[[#This Row],[Débours restant]]),0)) -> 0 | P29: =IF(RAE_SP_PRE[[#This Row],[Rôle ou catégorie]]="","",RAE_SP_PRE[[#This Row],[Main-d’œuvre]]+RAE_SP_PRE[[#This Row],[Débours]]) -> 0 | Q29: =IF(RAE_SP_PRE[[#This Row],[Rôle ou catégorie]]="","",IFERROR(INDEX(Referentiel[[Type de nature]],MATCH(RAE_SP_PRE[[#This Row],[Rôle ou catégorie]],Referentiel[[Entrée]],0)),"?")) -> 0 | R29: =IFERROR(INDEX(Taches[[Coefficient]],MATCH(RAE_SP_PRE[[#This Row],[Tâche]],Taches[[Entrée]],0)),1) -> 0
B30: =IF(RAE_SP_PRE[[#This Row],[Tâche]]="","",IFERROR(INDEX(Taches[[Description]],MATCH(RAE_SP_PRE[[#This Row],[Tâche]],Taches[[Entrée]],0)),"")) -> 0 | C30: =IF(RAE_SP_PRE[[#This Row],[Tâche]]="","",IFERROR(INDEX(Taches[[État]],MATCH(RAE_SP_PRE[[#This Row],[Tâche]],Taches[[Entrée]],0)),"")) -> 0 | J30: =IF(RAE_SP_PRE[[#This Row],[Rôle ou catégorie]]="","",IFERROR(INDEX(Referentiel[[Nature]],MATCH(RAE_SP_PRE[[#This Row],[Rôle ou catégorie]],Referentiel[[Entrée]],0)),"?")) -> 0 | K30: =IF(RAE_SP_PRE[[#This Row],[Rôle ou catégorie]]="","",IFERROR(INDEX(Referentiel[[Code comptable]],MATCH(RAE_SP_PRE[[#This Row],[Rôle ou catégorie]],Referentiel[[Entrée]],0)),"?")) -> 0 | L30: =IF(RAE_SP_PRE[[#This Row],[Rôle ou catégorie]]="","",IFERROR(INDEX(Referentiel[[Service]],MATCH(RAE_SP_PRE[[#This Row],[Rôle ou catégorie]],Referentiel[[Entrée]],0)),"?")&"") -> 0 | M30: =IF(RAE_SP_PRE[[#This Row],[Rôle ou catégorie]]="","",IFERROR(INDEX(Referentiel[[Taux horaire]],MATCH(RAE_SP_PRE[[#This Row],[Rôle ou catégorie]],Referentiel[[Entrée]],0)),"?")) -> 0 | N30: =IF(RAE_SP_PRE[[#This Row],[Rôle ou catégorie]]="","",IF(RAE_SP_PRE[[#This Row],[Type]]="Main-d’œuvre",N(RAE_SP_PRE[[#This Row],[Jours restants]])*HeuresParJour*RAE_SP_PRE[[#This Row],[Taux horaire]]*RAE_SP_PRE[[#This Row],[Coefficient]],0)) -> 0 | O30: =IF(RAE_SP_PRE[[#This Row],[Rôle ou catégorie]]="","",IF(RAE_SP_PRE[[#This Row],[Type]]="Hors main-d’œuvre",N(RAE_SP_PRE[[#This Row],[Débours restant]]),0)) -> 0 | P30: =IF(RAE_SP_PRE[[#This Row],[Rôle ou catégorie]]="","",RAE_SP_PRE[[#This Row],[Main-d’œuvre]]+RAE_SP_PRE[[#This Row],[Débours]]) -> 0 | Q30: =IF(RAE_SP_PRE[[#This Row],[Rôle ou catégorie]]="","",IFERROR(INDEX(Referentiel[[Type de nature]],MATCH(RAE_SP_PRE[[#This Row],[Rôle ou catégorie]],Referentiel[[Entrée]],0)),"?")) -> 0 | R30: =IFERROR(INDEX(Taches[[Coefficient]],MATCH(RAE_SP_PRE[[#This Row],[Tâche]],Taches[[Entrée]],0)),1) -> 0
B31: =IF(RAE_SP_PRE[[#This Row],[Tâche]]="","",IFERROR(INDEX(Taches[[Description]],MATCH(RAE_SP_PRE[[#This Row],[Tâche]],Taches[[Entrée]],0)),"")) -> 0 | C31: =IF(RAE_SP_PRE[[#This Row],[Tâche]]="","",IFERROR(INDEX(Taches[[État]],MATCH(RAE_SP_PRE[[#This Row],[Tâche]],Taches[[Entrée]],0)),"")) -> 0 | J31: =IF(RAE_SP_PRE[[#This Row],[Rôle ou catégorie]]="","",IFERROR(INDEX(Referentiel[[Nature]],MATCH(RAE_SP_PRE[[#This Row],[Rôle ou catégorie]],Referentiel[[Entrée]],0)),"?")) -> 0 | K31: =IF(RAE_SP_PRE[[#This Row],[Rôle ou catégorie]]="","",IFERROR(INDEX(Referentiel[[Code comptable]],MATCH(RAE_SP_PRE[[#This Row],[Rôle ou catégorie]],Referentiel[[Entrée]],0)),"?")) -> 0 | L31: =IF(RAE_SP_PRE[[#This Row],[Rôle ou catégorie]]="","",IFERROR(INDEX(Referentiel[[Service]],MATCH(RAE_SP_PRE[[#This Row],[Rôle ou catégorie]],Referentiel[[Entrée]],0)),"?")&"") -> 0 | M31: =IF(RAE_SP_PRE[[#This Row],[Rôle ou catégorie]]="","",IFERROR(INDEX(Referentiel[[Taux horaire]],MATCH(RAE_SP_PRE[[#This Row],[Rôle ou catégorie]],Referentiel[[Entrée]],0)),"?")) -> 0 | N31: =IF(RAE_SP_PRE[[#This Row],[Rôle ou catégorie]]="","",IF(RAE_SP_PRE[[#This Row],[Type]]="Main-d’œuvre",N(RAE_SP_PRE[[#This Row],[Jours restants]])*HeuresParJour*RAE_SP_PRE[[#This Row],[Taux horaire]]*RAE_SP_PRE[[#This Row],[Coefficient]],0)) -> 0 | O31: =IF(RAE_SP_PRE[[#This Row],[Rôle ou catégorie]]="","",IF(RAE_SP_PRE[[#This Row],[Type]]="Hors main-d’œuvre",N(RAE_SP_PRE[[#This Row],[Débours restant]]),0)) -> 0 | P31: =IF(RAE_SP_PRE[[#This Row],[Rôle ou catégorie]]="","",RAE_SP_PRE[[#This Row],[Main-d’œuvre]]+RAE_SP_PRE[[#This Row],[Débours]]) -> 0 | Q31: =IF(RAE_SP_PRE[[#This Row],[Rôle ou catégorie]]="","",IFERROR(INDEX(Referentiel[[Type de nature]],MATCH(RAE_SP_PRE[[#This Row],[Rôle ou catégorie]],Referentiel[[Entrée]],0)),"?")) -> 0 | R31: =IFERROR(INDEX(Taches[[Coefficient]],MATCH(RAE_SP_PRE[[#This Row],[Tâche]],Taches[[Entrée]],0)),1) -> 0
B32: =IF(RAE_SP_PRE[[#This Row],[Tâche]]="","",IFERROR(INDEX(Taches[[Description]],MATCH(RAE_SP_PRE[[#This Row],[Tâche]],Taches[[Entrée]],0)),"")) -> 0 | C32: =IF(RAE_SP_PRE[[#This Row],[Tâche]]="","",IFERROR(INDEX(Taches[[État]],MATCH(RAE_SP_PRE[[#This Row],[Tâche]],Taches[[Entrée]],0)),"")) -> 0 | J32: =IF(RAE_SP_PRE[[#This Row],[Rôle ou catégorie]]="","",IFERROR(INDEX(Referentiel[[Nature]],MATCH(RAE_SP_PRE[[#This Row],[Rôle ou catégorie]],Referentiel[[Entrée]],0)),"?")) -> 0 | K32: =IF(RAE_SP_PRE[[#This Row],[Rôle ou catégorie]]="","",IFERROR(INDEX(Referentiel[[Code comptable]],MATCH(RAE_SP_PRE[[#This Row],[Rôle ou catégorie]],Referentiel[[Entrée]],0)),"?")) -> 0 | L32: =IF(RAE_SP_PRE[[#This Row],[Rôle ou catégorie]]="","",IFERROR(INDEX(Referentiel[[Service]],MATCH(RAE_SP_PRE[[#This Row],[Rôle ou catégorie]],Referentiel[[Entrée]],0)),"?")&"") -> 0 | M32: =IF(RAE_SP_PRE[[#This Row],[Rôle ou catégorie]]="","",IFERROR(INDEX(Referentiel[[Taux horaire]],MATCH(RAE_SP_PRE[[#This Row],[Rôle ou catégorie]],Referentiel[[Entrée]],0)),"?")) -> 0 | N32: =IF(RAE_SP_PRE[[#This Row],[Rôle ou catégorie]]="","",IF(RAE_SP_PRE[[#This Row],[Type]]="Main-d’œuvre",N(RAE_SP_PRE[[#This Row],[Jours restants]])*HeuresParJour*RAE_SP_PRE[[#This Row],[Taux horaire]]*RAE_SP_PRE[[#This Row],[Coefficient]],0)) -> 0 | O32: =IF(RAE_SP_PRE[[#This Row],[Rôle ou catégorie]]="","",IF(RAE_SP_PRE[[#This Row],[Type]]="Hors main-d’œuvre",N(RAE_SP_PRE[[#This Row],[Débours restant]]),0)) -> 0 | P32: =IF(RAE_SP_PRE[[#This Row],[Rôle ou catégorie]]="","",RAE_SP_PRE[[#This Row],[Main-d’œuvre]]+RAE_SP_PRE[[#This Row],[Débours]]) -> 0 | Q32: =IF(RAE_SP_PRE[[#This Row],[Rôle ou catégorie]]="","",IFERROR(INDEX(Referentiel[[Type de nature]],MATCH(RAE_SP_PRE[[#This Row],[Rôle ou catégorie]],Referentiel[[Entrée]],0)),"?")) -> 0 | R32: =IFERROR(INDEX(Taches[[Coefficient]],MATCH(RAE_SP_PRE[[#This Row],[Tâche]],Taches[[Entrée]],0)),1) -> 0
A33: Total | F33: =SUBTOTAL(109,RAE_SP_PRE[[Budget]]) -> 0 | G33: =SUBTOTAL(109,RAE_SP_PRE[[Reste précédent]]) -> 0 | H33: =SUBTOTAL(109,RAE_SP_PRE[[Jours restants]]) -> 0 | I33: =SUBTOTAL(109,RAE_SP_PRE[[Débours restant]]) -> 0 | N33: =SUBTOTAL(109,RAE_SP_PRE[[Main-d’œuvre]]) -> 0 | O33: =SUBTOTAL(109,RAE_SP_PRE[[Débours]]) -> 0 | P33: =SUBTOTAL(109,RAE_SP_PRE[[Reste à engager]]) -> 0
A35: Les tâches terminées ne sont pas dans le fichier. Une tâche dont tout le reste vaut zéro est terminée à la date de la revue.
A36: © 2027 Exemple Industrie — Généré par Waterfall le 2027-02-15 — logiciel libre sous licence AGPL-3.0 — www.waterfall-project.pro

Sheet SP-MAT
A1: SP-MAT Matériel
A2: Revue du 2027-02-15 — une ligne par rôle ou par débours, comme au devis. La main-d’œuvre se saisit en jours de 8 heures, un débours en montant.
A4: Budget du sous-projet | B4: 7444
A5: Coûts réels imputés | B5: 3800
A6: Reste à engager du tableau | B6: =SUBTOTAL(109,RAE_SP_MAT[[Reste à engager]]) -> 0
A7: Provisions des risques identifiés | B7: 0
A9: Reste à engager | B9: =$B$6+$B$7 -> 0
A10: Projection (coûts réels + reste) | B10: =$B$5+$B$9 -> 0
A11: Écart au budget | B11: =$B$10-$B$4 -> 0
A12: Avancement financier | B12: =IF($B$10=0,"non calculable",$B$5/$B$10) -> 0
H14: Reste au 2027-02-15
A15: Tâche | B15: Description de la tâche | C15: État | D15: Rôle ou catégorie | E15: Désignation | F15: Budget | G15: Reste précédent | H15: Jours restants | I15: Débours restant | J15: Nature | K15: Code comptable | L15: Service | M15: Taux horaire | N15: Main-d’œuvre | O15: Débours | P15: Reste à engager | Q15: Type | R15: Coefficient | S15: ID ligne
A16: 1.2.1 Approvisionnement des lecteurs | B16: =IF(RAE_SP_MAT[[#This Row],[Tâche]]="","",IFERROR(INDEX(Taches[[Description]],MATCH(RAE_SP_MAT[[#This Row],[Tâche]],Taches[[Entrée]],0)),"")) -> 0 | C16: =IF(RAE_SP_MAT[[#This Row],[Tâche]]="","",IFERROR(INDEX(Taches[[État]],MATCH(RAE_SP_MAT[[#This Row],[Tâche]],Taches[[Entrée]],0)),"")) -> 0 | D16: Appareillage (fo-APPA) | E16: Commande 4500000101 — lecteurs, lot 1 | F16: 3672 | G16: 3600 | I16: 2400 | J16: =IF(RAE_SP_MAT[[#This Row],[Rôle ou catégorie]]="","",IFERROR(INDEX(Referentiel[[Nature]],MATCH(RAE_SP_MAT[[#This Row],[Rôle ou catégorie]],Referentiel[[Entrée]],0)),"?")) -> 0 | K16: =IF(RAE_SP_MAT[[#This Row],[Rôle ou catégorie]]="","",IFERROR(INDEX(Referentiel[[Code comptable]],MATCH(RAE_SP_MAT[[#This Row],[Rôle ou catégorie]],Referentiel[[Entrée]],0)),"?")) -> 0 | L16: =IF(RAE_SP_MAT[[#This Row],[Rôle ou catégorie]]="","",IFERROR(INDEX(Referentiel[[Service]],MATCH(RAE_SP_MAT[[#This Row],[Rôle ou catégorie]],Referentiel[[Entrée]],0)),"?")&"") -> 0 | M16: =IF(RAE_SP_MAT[[#This Row],[Rôle ou catégorie]]="","",IFERROR(INDEX(Referentiel[[Taux horaire]],MATCH(RAE_SP_MAT[[#This Row],[Rôle ou catégorie]],Referentiel[[Entrée]],0)),"?")) -> 0 | N16: =IF(RAE_SP_MAT[[#This Row],[Rôle ou catégorie]]="","",IF(RAE_SP_MAT[[#This Row],[Type]]="Main-d’œuvre",N(RAE_SP_MAT[[#This Row],[Jours restants]])*HeuresParJour*RAE_SP_MAT[[#This Row],[Taux horaire]]*RAE_SP_MAT[[#This Row],[Coefficient]],0)) -> 0 | O16: =IF(RAE_SP_MAT[[#This Row],[Rôle ou catégorie]]="","",IF(RAE_SP_MAT[[#This Row],[Type]]="Hors main-d’œuvre",N(RAE_SP_MAT[[#This Row],[Débours restant]]),0)) -> 0 | P16: =IF(RAE_SP_MAT[[#This Row],[Rôle ou catégorie]]="","",RAE_SP_MAT[[#This Row],[Main-d’œuvre]]+RAE_SP_MAT[[#This Row],[Débours]]) -> 0 | Q16: =IF(RAE_SP_MAT[[#This Row],[Rôle ou catégorie]]="","",IFERROR(INDEX(Referentiel[[Type de nature]],MATCH(RAE_SP_MAT[[#This Row],[Rôle ou catégorie]],Referentiel[[Entrée]],0)),"?")) -> 0 | R16: =IFERROR(INDEX(Taches[[Coefficient]],MATCH(RAE_SP_MAT[[#This Row],[Tâche]],Taches[[Entrée]],0)),1) -> 0 | S16: l-0201
A17: 1.2.1 Approvisionnement des lecteurs | B17: =IF(RAE_SP_MAT[[#This Row],[Tâche]]="","",IFERROR(INDEX(Taches[[Description]],MATCH(RAE_SP_MAT[[#This Row],[Tâche]],Taches[[Entrée]],0)),"")) -> 0 | C17: =IF(RAE_SP_MAT[[#This Row],[Tâche]]="","",IFERROR(INDEX(Taches[[État]],MATCH(RAE_SP_MAT[[#This Row],[Tâche]],Taches[[Entrée]],0)),"")) -> 0 | D17: Appareillage (fo-APPA) | E17: Commande 4500000103 — lecteurs, lot 2 | F17: 3672 | G17: 1600 | I17: 1200 | J17: =IF(RAE_SP_MAT[[#This Row],[Rôle ou catégorie]]="","",IFERROR(INDEX(Referentiel[[Nature]],MATCH(RAE_SP_MAT[[#This Row],[Rôle ou catégorie]],Referentiel[[Entrée]],0)),"?")) -> 0 | K17: =IF(RAE_SP_MAT[[#This Row],[Rôle ou catégorie]]="","",IFERROR(INDEX(Referentiel[[Code comptable]],MATCH(RAE_SP_MAT[[#This Row],[Rôle ou catégorie]],Referentiel[[Entrée]],0)),"?")) -> 0 | L17: =IF(RAE_SP_MAT[[#This Row],[Rôle ou catégorie]]="","",IFERROR(INDEX(Referentiel[[Service]],MATCH(RAE_SP_MAT[[#This Row],[Rôle ou catégorie]],Referentiel[[Entrée]],0)),"?")&"") -> 0 | M17: =IF(RAE_SP_MAT[[#This Row],[Rôle ou catégorie]]="","",IFERROR(INDEX(Referentiel[[Taux horaire]],MATCH(RAE_SP_MAT[[#This Row],[Rôle ou catégorie]],Referentiel[[Entrée]],0)),"?")) -> 0 | N17: =IF(RAE_SP_MAT[[#This Row],[Rôle ou catégorie]]="","",IF(RAE_SP_MAT[[#This Row],[Type]]="Main-d’œuvre",N(RAE_SP_MAT[[#This Row],[Jours restants]])*HeuresParJour*RAE_SP_MAT[[#This Row],[Taux horaire]]*RAE_SP_MAT[[#This Row],[Coefficient]],0)) -> 0 | O17: =IF(RAE_SP_MAT[[#This Row],[Rôle ou catégorie]]="","",IF(RAE_SP_MAT[[#This Row],[Type]]="Hors main-d’œuvre",N(RAE_SP_MAT[[#This Row],[Débours restant]]),0)) -> 0 | P17: =IF(RAE_SP_MAT[[#This Row],[Rôle ou catégorie]]="","",RAE_SP_MAT[[#This Row],[Main-d’œuvre]]+RAE_SP_MAT[[#This Row],[Débours]]) -> 0 | Q17: =IF(RAE_SP_MAT[[#This Row],[Rôle ou catégorie]]="","",IFERROR(INDEX(Referentiel[[Type de nature]],MATCH(RAE_SP_MAT[[#This Row],[Rôle ou catégorie]],Referentiel[[Entrée]],0)),"?")) -> 0 | R17: =IFERROR(INDEX(Taches[[Coefficient]],MATCH(RAE_SP_MAT[[#This Row],[Tâche]],Taches[[Entrée]],0)),1) -> 0 | S17: l-0204
B18: =IF(RAE_SP_MAT[[#This Row],[Tâche]]="","",IFERROR(INDEX(Taches[[Description]],MATCH(RAE_SP_MAT[[#This Row],[Tâche]],Taches[[Entrée]],0)),"")) -> 0 | C18: =IF(RAE_SP_MAT[[#This Row],[Tâche]]="","",IFERROR(INDEX(Taches[[État]],MATCH(RAE_SP_MAT[[#This Row],[Tâche]],Taches[[Entrée]],0)),"")) -> 0 | J18: =IF(RAE_SP_MAT[[#This Row],[Rôle ou catégorie]]="","",IFERROR(INDEX(Referentiel[[Nature]],MATCH(RAE_SP_MAT[[#This Row],[Rôle ou catégorie]],Referentiel[[Entrée]],0)),"?")) -> 0 | K18: =IF(RAE_SP_MAT[[#This Row],[Rôle ou catégorie]]="","",IFERROR(INDEX(Referentiel[[Code comptable]],MATCH(RAE_SP_MAT[[#This Row],[Rôle ou catégorie]],Referentiel[[Entrée]],0)),"?")) -> 0 | L18: =IF(RAE_SP_MAT[[#This Row],[Rôle ou catégorie]]="","",IFERROR(INDEX(Referentiel[[Service]],MATCH(RAE_SP_MAT[[#This Row],[Rôle ou catégorie]],Referentiel[[Entrée]],0)),"?")&"") -> 0 | M18: =IF(RAE_SP_MAT[[#This Row],[Rôle ou catégorie]]="","",IFERROR(INDEX(Referentiel[[Taux horaire]],MATCH(RAE_SP_MAT[[#This Row],[Rôle ou catégorie]],Referentiel[[Entrée]],0)),"?")) -> 0 | N18: =IF(RAE_SP_MAT[[#This Row],[Rôle ou catégorie]]="","",IF(RAE_SP_MAT[[#This Row],[Type]]="Main-d’œuvre",N(RAE_SP_MAT[[#This Row],[Jours restants]])*HeuresParJour*RAE_SP_MAT[[#This Row],[Taux horaire]]*RAE_SP_MAT[[#This Row],[Coefficient]],0)) -> 0 | O18: =IF(RAE_SP_MAT[[#This Row],[Rôle ou catégorie]]="","",IF(RAE_SP_MAT[[#This Row],[Type]]="Hors main-d’œuvre",N(RAE_SP_MAT[[#This Row],[Débours restant]]),0)) -> 0 | P18: =IF(RAE_SP_MAT[[#This Row],[Rôle ou catégorie]]="","",RAE_SP_MAT[[#This Row],[Main-d’œuvre]]+RAE_SP_MAT[[#This Row],[Débours]]) -> 0 | Q18: =IF(RAE_SP_MAT[[#This Row],[Rôle ou catégorie]]="","",IFERROR(INDEX(Referentiel[[Type de nature]],MATCH(RAE_SP_MAT[[#This Row],[Rôle ou catégorie]],Referentiel[[Entrée]],0)),"?")) -> 0 | R18: =IFERROR(INDEX(Taches[[Coefficient]],MATCH(RAE_SP_MAT[[#This Row],[Tâche]],Taches[[Entrée]],0)),1) -> 0
B19: =IF(RAE_SP_MAT[[#This Row],[Tâche]]="","",IFERROR(INDEX(Taches[[Description]],MATCH(RAE_SP_MAT[[#This Row],[Tâche]],Taches[[Entrée]],0)),"")) -> 0 | C19: =IF(RAE_SP_MAT[[#This Row],[Tâche]]="","",IFERROR(INDEX(Taches[[État]],MATCH(RAE_SP_MAT[[#This Row],[Tâche]],Taches[[Entrée]],0)),"")) -> 0 | J19: =IF(RAE_SP_MAT[[#This Row],[Rôle ou catégorie]]="","",IFERROR(INDEX(Referentiel[[Nature]],MATCH(RAE_SP_MAT[[#This Row],[Rôle ou catégorie]],Referentiel[[Entrée]],0)),"?")) -> 0 | K19: =IF(RAE_SP_MAT[[#This Row],[Rôle ou catégorie]]="","",IFERROR(INDEX(Referentiel[[Code comptable]],MATCH(RAE_SP_MAT[[#This Row],[Rôle ou catégorie]],Referentiel[[Entrée]],0)),"?")) -> 0 | L19: =IF(RAE_SP_MAT[[#This Row],[Rôle ou catégorie]]="","",IFERROR(INDEX(Referentiel[[Service]],MATCH(RAE_SP_MAT[[#This Row],[Rôle ou catégorie]],Referentiel[[Entrée]],0)),"?")&"") -> 0 | M19: =IF(RAE_SP_MAT[[#This Row],[Rôle ou catégorie]]="","",IFERROR(INDEX(Referentiel[[Taux horaire]],MATCH(RAE_SP_MAT[[#This Row],[Rôle ou catégorie]],Referentiel[[Entrée]],0)),"?")) -> 0 | N19: =IF(RAE_SP_MAT[[#This Row],[Rôle ou catégorie]]="","",IF(RAE_SP_MAT[[#This Row],[Type]]="Main-d’œuvre",N(RAE_SP_MAT[[#This Row],[Jours restants]])*HeuresParJour*RAE_SP_MAT[[#This Row],[Taux horaire]]*RAE_SP_MAT[[#This Row],[Coefficient]],0)) -> 0 | O19: =IF(RAE_SP_MAT[[#This Row],[Rôle ou catégorie]]="","",IF(RAE_SP_MAT[[#This Row],[Type]]="Hors main-d’œuvre",N(RAE_SP_MAT[[#This Row],[Débours restant]]),0)) -> 0 | P19: =IF(RAE_SP_MAT[[#This Row],[Rôle ou catégorie]]="","",RAE_SP_MAT[[#This Row],[Main-d’œuvre]]+RAE_SP_MAT[[#This Row],[Débours]]) -> 0 | Q19: =IF(RAE_SP_MAT[[#This Row],[Rôle ou catégorie]]="","",IFERROR(INDEX(Referentiel[[Type de nature]],MATCH(RAE_SP_MAT[[#This Row],[Rôle ou catégorie]],Referentiel[[Entrée]],0)),"?")) -> 0 | R19: =IFERROR(INDEX(Taches[[Coefficient]],MATCH(RAE_SP_MAT[[#This Row],[Tâche]],Taches[[Entrée]],0)),1) -> 0
B20: =IF(RAE_SP_MAT[[#This Row],[Tâche]]="","",IFERROR(INDEX(Taches[[Description]],MATCH(RAE_SP_MAT[[#This Row],[Tâche]],Taches[[Entrée]],0)),"")) -> 0 | C20: =IF(RAE_SP_MAT[[#This Row],[Tâche]]="","",IFERROR(INDEX(Taches[[État]],MATCH(RAE_SP_MAT[[#This Row],[Tâche]],Taches[[Entrée]],0)),"")) -> 0 | J20: =IF(RAE_SP_MAT[[#This Row],[Rôle ou catégorie]]="","",IFERROR(INDEX(Referentiel[[Nature]],MATCH(RAE_SP_MAT[[#This Row],[Rôle ou catégorie]],Referentiel[[Entrée]],0)),"?")) -> 0 | K20: =IF(RAE_SP_MAT[[#This Row],[Rôle ou catégorie]]="","",IFERROR(INDEX(Referentiel[[Code comptable]],MATCH(RAE_SP_MAT[[#This Row],[Rôle ou catégorie]],Referentiel[[Entrée]],0)),"?")) -> 0 | L20: =IF(RAE_SP_MAT[[#This Row],[Rôle ou catégorie]]="","",IFERROR(INDEX(Referentiel[[Service]],MATCH(RAE_SP_MAT[[#This Row],[Rôle ou catégorie]],Referentiel[[Entrée]],0)),"?")&"") -> 0 | M20: =IF(RAE_SP_MAT[[#This Row],[Rôle ou catégorie]]="","",IFERROR(INDEX(Referentiel[[Taux horaire]],MATCH(RAE_SP_MAT[[#This Row],[Rôle ou catégorie]],Referentiel[[Entrée]],0)),"?")) -> 0 | N20: =IF(RAE_SP_MAT[[#This Row],[Rôle ou catégorie]]="","",IF(RAE_SP_MAT[[#This Row],[Type]]="Main-d’œuvre",N(RAE_SP_MAT[[#This Row],[Jours restants]])*HeuresParJour*RAE_SP_MAT[[#This Row],[Taux horaire]]*RAE_SP_MAT[[#This Row],[Coefficient]],0)) -> 0 | O20: =IF(RAE_SP_MAT[[#This Row],[Rôle ou catégorie]]="","",IF(RAE_SP_MAT[[#This Row],[Type]]="Hors main-d’œuvre",N(RAE_SP_MAT[[#This Row],[Débours restant]]),0)) -> 0 | P20: =IF(RAE_SP_MAT[[#This Row],[Rôle ou catégorie]]="","",RAE_SP_MAT[[#This Row],[Main-d’œuvre]]+RAE_SP_MAT[[#This Row],[Débours]]) -> 0 | Q20: =IF(RAE_SP_MAT[[#This Row],[Rôle ou catégorie]]="","",IFERROR(INDEX(Referentiel[[Type de nature]],MATCH(RAE_SP_MAT[[#This Row],[Rôle ou catégorie]],Referentiel[[Entrée]],0)),"?")) -> 0 | R20: =IFERROR(INDEX(Taches[[Coefficient]],MATCH(RAE_SP_MAT[[#This Row],[Tâche]],Taches[[Entrée]],0)),1) -> 0
B21: =IF(RAE_SP_MAT[[#This Row],[Tâche]]="","",IFERROR(INDEX(Taches[[Description]],MATCH(RAE_SP_MAT[[#This Row],[Tâche]],Taches[[Entrée]],0)),"")) -> 0 | C21: =IF(RAE_SP_MAT[[#This Row],[Tâche]]="","",IFERROR(INDEX(Taches[[État]],MATCH(RAE_SP_MAT[[#This Row],[Tâche]],Taches[[Entrée]],0)),"")) -> 0 | J21: =IF(RAE_SP_MAT[[#This Row],[Rôle ou catégorie]]="","",IFERROR(INDEX(Referentiel[[Nature]],MATCH(RAE_SP_MAT[[#This Row],[Rôle ou catégorie]],Referentiel[[Entrée]],0)),"?")) -> 0 | K21: =IF(RAE_SP_MAT[[#This Row],[Rôle ou catégorie]]="","",IFERROR(INDEX(Referentiel[[Code comptable]],MATCH(RAE_SP_MAT[[#This Row],[Rôle ou catégorie]],Referentiel[[Entrée]],0)),"?")) -> 0 | L21: =IF(RAE_SP_MAT[[#This Row],[Rôle ou catégorie]]="","",IFERROR(INDEX(Referentiel[[Service]],MATCH(RAE_SP_MAT[[#This Row],[Rôle ou catégorie]],Referentiel[[Entrée]],0)),"?")&"") -> 0 | M21: =IF(RAE_SP_MAT[[#This Row],[Rôle ou catégorie]]="","",IFERROR(INDEX(Referentiel[[Taux horaire]],MATCH(RAE_SP_MAT[[#This Row],[Rôle ou catégorie]],Referentiel[[Entrée]],0)),"?")) -> 0 | N21: =IF(RAE_SP_MAT[[#This Row],[Rôle ou catégorie]]="","",IF(RAE_SP_MAT[[#This Row],[Type]]="Main-d’œuvre",N(RAE_SP_MAT[[#This Row],[Jours restants]])*HeuresParJour*RAE_SP_MAT[[#This Row],[Taux horaire]]*RAE_SP_MAT[[#This Row],[Coefficient]],0)) -> 0 | O21: =IF(RAE_SP_MAT[[#This Row],[Rôle ou catégorie]]="","",IF(RAE_SP_MAT[[#This Row],[Type]]="Hors main-d’œuvre",N(RAE_SP_MAT[[#This Row],[Débours restant]]),0)) -> 0 | P21: =IF(RAE_SP_MAT[[#This Row],[Rôle ou catégorie]]="","",RAE_SP_MAT[[#This Row],[Main-d’œuvre]]+RAE_SP_MAT[[#This Row],[Débours]]) -> 0 | Q21: =IF(RAE_SP_MAT[[#This Row],[Rôle ou catégorie]]="","",IFERROR(INDEX(Referentiel[[Type de nature]],MATCH(RAE_SP_MAT[[#This Row],[Rôle ou catégorie]],Referentiel[[Entrée]],0)),"?")) -> 0 | R21: =IFERROR(INDEX(Taches[[Coefficient]],MATCH(RAE_SP_MAT[[#This Row],[Tâche]],Taches[[Entrée]],0)),1) -> 0
B22: =IF(RAE_SP_MAT[[#This Row],[Tâche]]="","",IFERROR(INDEX(Taches[[Description]],MATCH(RAE_SP_MAT[[#This Row],[Tâche]],Taches[[Entrée]],0)),"")) -> 0 | C22: =IF(RAE_SP_MAT[[#This Row],[Tâche]]="","",IFERROR(INDEX(Taches[[État]],MATCH(RAE_SP_MAT[[#This Row],[Tâche]],Taches[[Entrée]],0)),"")) -> 0 | J22: =IF(RAE_SP_MAT[[#This Row],[Rôle ou catégorie]]="","",IFERROR(INDEX(Referentiel[[Nature]],MATCH(RAE_SP_MAT[[#This Row],[Rôle ou catégorie]],Referentiel[[Entrée]],0)),"?")) -> 0 | K22: =IF(RAE_SP_MAT[[#This Row],[Rôle ou catégorie]]="","",IFERROR(INDEX(Referentiel[[Code comptable]],MATCH(RAE_SP_MAT[[#This Row],[Rôle ou catégorie]],Referentiel[[Entrée]],0)),"?")) -> 0 | L22: =IF(RAE_SP_MAT[[#This Row],[Rôle ou catégorie]]="","",IFERROR(INDEX(Referentiel[[Service]],MATCH(RAE_SP_MAT[[#This Row],[Rôle ou catégorie]],Referentiel[[Entrée]],0)),"?")&"") -> 0 | M22: =IF(RAE_SP_MAT[[#This Row],[Rôle ou catégorie]]="","",IFERROR(INDEX(Referentiel[[Taux horaire]],MATCH(RAE_SP_MAT[[#This Row],[Rôle ou catégorie]],Referentiel[[Entrée]],0)),"?")) -> 0 | N22: =IF(RAE_SP_MAT[[#This Row],[Rôle ou catégorie]]="","",IF(RAE_SP_MAT[[#This Row],[Type]]="Main-d’œuvre",N(RAE_SP_MAT[[#This Row],[Jours restants]])*HeuresParJour*RAE_SP_MAT[[#This Row],[Taux horaire]]*RAE_SP_MAT[[#This Row],[Coefficient]],0)) -> 0 | O22: =IF(RAE_SP_MAT[[#This Row],[Rôle ou catégorie]]="","",IF(RAE_SP_MAT[[#This Row],[Type]]="Hors main-d’œuvre",N(RAE_SP_MAT[[#This Row],[Débours restant]]),0)) -> 0 | P22: =IF(RAE_SP_MAT[[#This Row],[Rôle ou catégorie]]="","",RAE_SP_MAT[[#This Row],[Main-d’œuvre]]+RAE_SP_MAT[[#This Row],[Débours]]) -> 0 | Q22: =IF(RAE_SP_MAT[[#This Row],[Rôle ou catégorie]]="","",IFERROR(INDEX(Referentiel[[Type de nature]],MATCH(RAE_SP_MAT[[#This Row],[Rôle ou catégorie]],Referentiel[[Entrée]],0)),"?")) -> 0 | R22: =IFERROR(INDEX(Taches[[Coefficient]],MATCH(RAE_SP_MAT[[#This Row],[Tâche]],Taches[[Entrée]],0)),1) -> 0
B23: =IF(RAE_SP_MAT[[#This Row],[Tâche]]="","",IFERROR(INDEX(Taches[[Description]],MATCH(RAE_SP_MAT[[#This Row],[Tâche]],Taches[[Entrée]],0)),"")) -> 0 | C23: =IF(RAE_SP_MAT[[#This Row],[Tâche]]="","",IFERROR(INDEX(Taches[[État]],MATCH(RAE_SP_MAT[[#This Row],[Tâche]],Taches[[Entrée]],0)),"")) -> 0 | J23: =IF(RAE_SP_MAT[[#This Row],[Rôle ou catégorie]]="","",IFERROR(INDEX(Referentiel[[Nature]],MATCH(RAE_SP_MAT[[#This Row],[Rôle ou catégorie]],Referentiel[[Entrée]],0)),"?")) -> 0 | K23: =IF(RAE_SP_MAT[[#This Row],[Rôle ou catégorie]]="","",IFERROR(INDEX(Referentiel[[Code comptable]],MATCH(RAE_SP_MAT[[#This Row],[Rôle ou catégorie]],Referentiel[[Entrée]],0)),"?")) -> 0 | L23: =IF(RAE_SP_MAT[[#This Row],[Rôle ou catégorie]]="","",IFERROR(INDEX(Referentiel[[Service]],MATCH(RAE_SP_MAT[[#This Row],[Rôle ou catégorie]],Referentiel[[Entrée]],0)),"?")&"") -> 0 | M23: =IF(RAE_SP_MAT[[#This Row],[Rôle ou catégorie]]="","",IFERROR(INDEX(Referentiel[[Taux horaire]],MATCH(RAE_SP_MAT[[#This Row],[Rôle ou catégorie]],Referentiel[[Entrée]],0)),"?")) -> 0 | N23: =IF(RAE_SP_MAT[[#This Row],[Rôle ou catégorie]]="","",IF(RAE_SP_MAT[[#This Row],[Type]]="Main-d’œuvre",N(RAE_SP_MAT[[#This Row],[Jours restants]])*HeuresParJour*RAE_SP_MAT[[#This Row],[Taux horaire]]*RAE_SP_MAT[[#This Row],[Coefficient]],0)) -> 0 | O23: =IF(RAE_SP_MAT[[#This Row],[Rôle ou catégorie]]="","",IF(RAE_SP_MAT[[#This Row],[Type]]="Hors main-d’œuvre",N(RAE_SP_MAT[[#This Row],[Débours restant]]),0)) -> 0 | P23: =IF(RAE_SP_MAT[[#This Row],[Rôle ou catégorie]]="","",RAE_SP_MAT[[#This Row],[Main-d’œuvre]]+RAE_SP_MAT[[#This Row],[Débours]]) -> 0 | Q23: =IF(RAE_SP_MAT[[#This Row],[Rôle ou catégorie]]="","",IFERROR(INDEX(Referentiel[[Type de nature]],MATCH(RAE_SP_MAT[[#This Row],[Rôle ou catégorie]],Referentiel[[Entrée]],0)),"?")) -> 0 | R23: =IFERROR(INDEX(Taches[[Coefficient]],MATCH(RAE_SP_MAT[[#This Row],[Tâche]],Taches[[Entrée]],0)),1) -> 0
B24: =IF(RAE_SP_MAT[[#This Row],[Tâche]]="","",IFERROR(INDEX(Taches[[Description]],MATCH(RAE_SP_MAT[[#This Row],[Tâche]],Taches[[Entrée]],0)),"")) -> 0 | C24: =IF(RAE_SP_MAT[[#This Row],[Tâche]]="","",IFERROR(INDEX(Taches[[État]],MATCH(RAE_SP_MAT[[#This Row],[Tâche]],Taches[[Entrée]],0)),"")) -> 0 | J24: =IF(RAE_SP_MAT[[#This Row],[Rôle ou catégorie]]="","",IFERROR(INDEX(Referentiel[[Nature]],MATCH(RAE_SP_MAT[[#This Row],[Rôle ou catégorie]],Referentiel[[Entrée]],0)),"?")) -> 0 | K24: =IF(RAE_SP_MAT[[#This Row],[Rôle ou catégorie]]="","",IFERROR(INDEX(Referentiel[[Code comptable]],MATCH(RAE_SP_MAT[[#This Row],[Rôle ou catégorie]],Referentiel[[Entrée]],0)),"?")) -> 0 | L24: =IF(RAE_SP_MAT[[#This Row],[Rôle ou catégorie]]="","",IFERROR(INDEX(Referentiel[[Service]],MATCH(RAE_SP_MAT[[#This Row],[Rôle ou catégorie]],Referentiel[[Entrée]],0)),"?")&"") -> 0 | M24: =IF(RAE_SP_MAT[[#This Row],[Rôle ou catégorie]]="","",IFERROR(INDEX(Referentiel[[Taux horaire]],MATCH(RAE_SP_MAT[[#This Row],[Rôle ou catégorie]],Referentiel[[Entrée]],0)),"?")) -> 0 | N24: =IF(RAE_SP_MAT[[#This Row],[Rôle ou catégorie]]="","",IF(RAE_SP_MAT[[#This Row],[Type]]="Main-d’œuvre",N(RAE_SP_MAT[[#This Row],[Jours restants]])*HeuresParJour*RAE_SP_MAT[[#This Row],[Taux horaire]]*RAE_SP_MAT[[#This Row],[Coefficient]],0)) -> 0 | O24: =IF(RAE_SP_MAT[[#This Row],[Rôle ou catégorie]]="","",IF(RAE_SP_MAT[[#This Row],[Type]]="Hors main-d’œuvre",N(RAE_SP_MAT[[#This Row],[Débours restant]]),0)) -> 0 | P24: =IF(RAE_SP_MAT[[#This Row],[Rôle ou catégorie]]="","",RAE_SP_MAT[[#This Row],[Main-d’œuvre]]+RAE_SP_MAT[[#This Row],[Débours]]) -> 0 | Q24: =IF(RAE_SP_MAT[[#This Row],[Rôle ou catégorie]]="","",IFERROR(INDEX(Referentiel[[Type de nature]],MATCH(RAE_SP_MAT[[#This Row],[Rôle ou catégorie]],Referentiel[[Entrée]],0)),"?")) -> 0 | R24: =IFERROR(INDEX(Taches[[Coefficient]],MATCH(RAE_SP_MAT[[#This Row],[Tâche]],Taches[[Entrée]],0)),1) -> 0
B25: =IF(RAE_SP_MAT[[#This Row],[Tâche]]="","",IFERROR(INDEX(Taches[[Description]],MATCH(RAE_SP_MAT[[#This Row],[Tâche]],Taches[[Entrée]],0)),"")) -> 0 | C25: =IF(RAE_SP_MAT[[#This Row],[Tâche]]="","",IFERROR(INDEX(Taches[[État]],MATCH(RAE_SP_MAT[[#This Row],[Tâche]],Taches[[Entrée]],0)),"")) -> 0 | J25: =IF(RAE_SP_MAT[[#This Row],[Rôle ou catégorie]]="","",IFERROR(INDEX(Referentiel[[Nature]],MATCH(RAE_SP_MAT[[#This Row],[Rôle ou catégorie]],Referentiel[[Entrée]],0)),"?")) -> 0 | K25: =IF(RAE_SP_MAT[[#This Row],[Rôle ou catégorie]]="","",IFERROR(INDEX(Referentiel[[Code comptable]],MATCH(RAE_SP_MAT[[#This Row],[Rôle ou catégorie]],Referentiel[[Entrée]],0)),"?")) -> 0 | L25: =IF(RAE_SP_MAT[[#This Row],[Rôle ou catégorie]]="","",IFERROR(INDEX(Referentiel[[Service]],MATCH(RAE_SP_MAT[[#This Row],[Rôle ou catégorie]],Referentiel[[Entrée]],0)),"?")&"") -> 0 | M25: =IF(RAE_SP_MAT[[#This Row],[Rôle ou catégorie]]="","",IFERROR(INDEX(Referentiel[[Taux horaire]],MATCH(RAE_SP_MAT[[#This Row],[Rôle ou catégorie]],Referentiel[[Entrée]],0)),"?")) -> 0 | N25: =IF(RAE_SP_MAT[[#This Row],[Rôle ou catégorie]]="","",IF(RAE_SP_MAT[[#This Row],[Type]]="Main-d’œuvre",N(RAE_SP_MAT[[#This Row],[Jours restants]])*HeuresParJour*RAE_SP_MAT[[#This Row],[Taux horaire]]*RAE_SP_MAT[[#This Row],[Coefficient]],0)) -> 0 | O25: =IF(RAE_SP_MAT[[#This Row],[Rôle ou catégorie]]="","",IF(RAE_SP_MAT[[#This Row],[Type]]="Hors main-d’œuvre",N(RAE_SP_MAT[[#This Row],[Débours restant]]),0)) -> 0 | P25: =IF(RAE_SP_MAT[[#This Row],[Rôle ou catégorie]]="","",RAE_SP_MAT[[#This Row],[Main-d’œuvre]]+RAE_SP_MAT[[#This Row],[Débours]]) -> 0 | Q25: =IF(RAE_SP_MAT[[#This Row],[Rôle ou catégorie]]="","",IFERROR(INDEX(Referentiel[[Type de nature]],MATCH(RAE_SP_MAT[[#This Row],[Rôle ou catégorie]],Referentiel[[Entrée]],0)),"?")) -> 0 | R25: =IFERROR(INDEX(Taches[[Coefficient]],MATCH(RAE_SP_MAT[[#This Row],[Tâche]],Taches[[Entrée]],0)),1) -> 0
